Workbook
Name BE_Contribution: tblBreakEven[Total Contribution (CM)]
Name BE_Cost: tblBreakEven[Total Variable Cost]+tblBreakEven[Fixed Costs (total)]
Name BE_Fixed: tblBreakEven[Fixed Costs (total)]
Name BE_MOS: tblBreakEven[Margin of Safety (%)]
Name BE_Revenue: tblBreakEven[[Total Revenue ]]
Name BE_SalesValue: tblBreakEven[Break-even Sales Value]
Name BE_Units: tblBreakEven[Break-even Units]
Name BE_Years: tblBreakEven[[Year ]]
Name CF_ClosingCash: 'Cash Flow'!$B$21:$G$21
Name CF_FinancingCash: 'Cash Flow'!$B$18:$G$18
Name CF_InvestingCash.: 'Cash Flow'!$B$12:$G$12
Name CF_NetChange: 'Cash Flow'!$B$19:$G$19
Name CF_OperatingCash: 'Cash Flow'!$B$9:$G$9
Name EBIT: tblPL[EBIT]
Name Net_Profit: tblPL[Net Profit]
Name Profit_Before_Tax: tblPL[Profit Before Tax]
Name Revenue_Values: tblRevenue[Total Revenue]
Name Total_Costs: tblCosts[Total Costs]
Name Total_Fixed_Costs: tblCosts[Total Fixed Costs]
Name Total_Variable_Costs: tblCosts[Total Variable Costs]
Name Year_Values.: tblRevenue[Year]

Sheet Inputs
A1: General Assumptions
A2: Category | B2: Value | D2: Notes
A3: Start Year | B3: 2025 | D3: Model starting year
A4: Currency | B4: BDT | D4: Base currency
A5: Inflation Rate (%) | B5: 6% | D5: Annual inflation
A7: Sales Assumptions
A8: Product/Service | B8: Unit Price (BDT) | C8: Monthly Volume | D8: Growth Rate (%)
A9: Product A | B9: 500 | C9: 1000 | D9: 5%
A10: Product B | B10: 800 | C10: 500 | D10: 3%
A11: Service C | B11: 1200 | C11: 200 | D11: 4%
A12: Annual units | C12: =(C9+C10+C11)*12 -> 20400
A14: Fixed Costs
A15: Cost Item | B15: Monthly Cost (BDT) | C15: Annual Growth (%) | D15: Notes
A16: Rent | B16: 50000 | C16: 5% | D16: Office space
A17: Salaries | B17: 200000 | C17: 7% | D17: Staff salaries
A18: Utilities | B18: 20000 | C18: 4% | D18: Electricity, Internet
A20: Variable Costs
A21: Cost Item | B21: % of Sales Revenue | D21: Notes
A22: Raw Materials | B22: 30% | D22: Based on sales
A23: Packaging | B23: 5% | D23: Per product
A24: Delivery | B24: 3% | D24: Per order
A25: Commission / Transaction fees | B25: 0.02 | D25: Basis on sales
A26: Marketing | B26: 0.05 | D26: On sales
A28: Investment & Loan
A29: Item | B29: Value (BDT) | C29: Interest Rate (%) | D29: Term (Years)
A30: Initial Investment | B30: 1000000 | C30: - | D30: -
A31: Bank Loan | B31: 500000 | C31: 10% | D31: 5
A33: Fixed Assets
A34: Item | B34: Value (BDT) | C34: Useful Life (Years) | D34: Notes
A35: Office Equipment | B35: 1000000 | C35: 5 | D35: Computers, printer
A36: Furniture & Fixture | B36: 150000 | C36: 5 | D36: Office furniture
A37: Total Assets | B37: =B35+B36 -> 1150000 | D37: Matches Initial Investment
A39: Tax & Depreciation
A40: Category | B40: Rate/Value | D40: Notes
A41: Corporate Tax Rate | B41: 25% | D41: Standard tax
A42: Depreciation Rate (%) | B42: 10% | D42: On fixed assets
A44: Working Capital Assumptions
A45: Category | B45: Value (Days) | D45: Notes
A46: Accounts Receivable | B46: 30 | D46: Customer payment terms
A47: Inventory Holding | B47: 20 | D47: Avg days stock held
...

Sheet Revenue Forecast
A1: Year | B1: Product A Units | C1: Growth % A | D1: Product A Unit Price | E1: Revenue A | F1: Product B Units | G1: Growth % B | H1: Product B Unit Price | I1: Revenue B | J1: Service C Units | K1: Growth % C | L1: Service C Unit Price | M1: Revenue C | N1: Total Revenue
A2: 2025 | B2: =Inputs!C9*12 -> 12000 | C2: =Inputs!$D$9 -> 5% | D2: =Inputs!B9 -> 500 | E2: =B2*D2 -> 6000000 | F2: =Inputs!C10*12 -> 6000 | G2: =Inputs!$D$10 -> 3% | H2: =Inputs!B10 -> 800 | I2: =F2*H2 -> 4800000 | J2: =Inputs!C11*12 -> 2400 | K2: =Inputs!$D$11 -> 4% | L2: =Inputs!B11 -> 1200 | M2: =J2*L2 -> 2880000 | N2: =E2+I2+M2 -> 13680000
A3: 2026 | B3: =B2 * (1 + C2) -> 12600 | C3: =Inputs!$D$9 -> 5% | D3: =D2 * (1 + Inputs!$B$5) -> 530 | E3: =B3 * D2 -> 6300000 | F3: =F2 * (1 + G2) -> 6180 | G3: =Inputs!$D$10 -> 3% | H3: =H2*(1+Inputs!$B$5) -> 848 | I3: =F3 * H2 -> 4944000 | J3: =J2 * (1 + K2) -> 2496 | K3: =Inputs!$D$11 -> 4% | L3: =L2 * (1 + Inputs!$B$5) -> 1272 | M3: =J3 * L3 -> 3174912 | N3: =E3+I3+M3 -> 14418912
A4: 2027 | B4: =B3 * (1 + C3) -> 13230 | C4: =Inputs!$D$9 -> 5% | D4: =D3 * (1 + Inputs!$B$5) -> 561.8 | E4: =B4 * D3 -> 7011900 | F4: =F3 * (1 + G2) -> 6365.4 | G4: =Inputs!$D$10 -> 3% | H4: =H3*(1+Inputs!$B$5) -> 898.88 | I4: =F4*H4 -> 5721730.8 | J4: =J3 * (1 + K2) -> 2595.84 | K4: =Inputs!$D$11 -> 4% | L4: =L3 * (1 + Inputs!$B$5) -> 1348.32 | M4: =J4 * L4 -> 3500023 | N4: =E4+I4+M4 -> 16233654
A5: 2028 | B5: =B4 * (1 + C3) -> 13891.5 | C5: =Inputs!$D$9 -> 5% | D5: =D4* (1 + Inputs!$B$5) -> 595.508 | E5: =B5 * D4 -> 7804244.7 | F5: =F4 * (1 + G2) -> 6556.362 | G5: =Inputs!$D$10 -> 3% | H5: =H4*(1+Inputs!$B$5) -> 952.8128 | I5: =F5*H5 -> 6246985.6 | J5: =J4 * (1 + K2) -> 2699.6736 | K5: =Inputs!$D$11 -> 4% | L5: =L4 * (1 + Inputs!$B$5) -> 1429.2192 | M5: =J5 * L5 -> 3858425.3 | N5: =E5+I5+M5 -> 17909656
A6: 2029 | B6: =B5 * (1 + C3) -> 14586.075 | C6: =Inputs!$D$9 -> 5% | D6: =D5 * (1 + Inputs!$B$5) -> 631.23848 | E6: =B6 * D5 -> 8686124.4 | F6: =F5 * (1 + G2) -> 6753.0529 | G6: =Inputs!$D$10 -> 3% | H6: =H5*(1+Inputs!$B$5) -> 1009.9816 | I6: =F6*H6 -> 6820458.9 | J6: =J5 * (1 + K2) -> 2807.6605 | K6: =Inputs!$D$11 -> 4% | L6: =L5 * (1 + Inputs!$B$5) -> 1514.9724 | M6: =J6 * L6 -> 4253528.1 | N6: =E6+I6+M6 -> 19760111
A7: 2030 | B7: =B6 * (1 + C3) -> 15315.379 | C7: =Inputs!$D$9 -> 5% | D7: =D6 * (1 + Inputs!$B$5) -> 669.11279 | E7: =B7 * D6 -> 9667656.4 | F7: =F6 * (1 + G2) -> 6955.6444 | G7: =Inputs!$D$10 -> 3% | H7: =H6*(1+Inputs!$B$5) -> 1070.5805 | I7: =F7*H7 -> 7446577 | J7: =J6* (1 + K2) -> 2919.967 | K7: =Inputs!$D$11 -> 4% | L7: =L6 * (1 + Inputs!$B$5) -> 1605.8707 | M7: =J7 * L7 -> 4689089.4 | N7: =E7+I7+M7 -> 21803323

Sheet Cost Breakdown
A1: Year | B1: Total Revenue | C1: Rent | D1: Salaries | E1: Utilities | F1: Total Fixed Costs | G1: Raw Materials (30%) | H1: Packaging (5%) | I1: Delivery (3%) | J1: Commission (2%) | K1: Marketing (5%) | L1: Total Variable Costs | M1: Total Costs
A2: 2025 | B2: ='Revenue Forecast'!N2 -> 13680000 | C2: =Inputs!B16 -> 50000 | D2: =Inputs!B17 -> 200000 | E2: =Inputs!B18 -> 20000 | F2: =C2+D2+E2 -> 270000 | G2: =B2 * Inputs!$B$22 -> 4104000 | H2: =B2 * Inputs!$B$23 -> 684000 | I2: =B2 * Inputs!$B$24 -> 410400 | J2: =B2 * Inputs!$B$25 -> 273600 | K2: =B2 * Inputs!$B$26 -> 684000 | L2: =G2+H2+I2+J2+K2 -> 6156000 | M2: =F2 + L2 -> 6426000
A3: 2026 | B3: ='Revenue Forecast'!N3 -> 14418912 | C3: =C2*(1+Inputs!C16) -> 52500 | D3: =D2 * (1 + Inputs!$C$17) -> 214000 | E3: =E2 * (1 + Inputs!$C$18) -> 20800 | F3: =C3+D3+E3 -> 287300 | G3: =B3 * Inputs!$B$22 -> 4325673.6 | H3: =B3 * Inputs!$B$23 -> 720945.6 | I3: =B3 * Inputs!$B$24 -> 432567.36 | J3: =B3 * Inputs!$B$25 -> 288378.24 | K3: =B3 * Inputs!$B$26 -> 720945.6 | L3: =G3+H3+I3+J3+K3 -> 6488510.4 | M3: =F3 + L3 -> 6775810.4
A4: 2027 | B4: ='Revenue Forecast'!N4 -> 16233654 | C4: =C3*(1+Inputs!C17) -> 56175 | D4: =D3 * (1 + Inputs!$C$17) -> 228980 | E4: =E3 * (1 + Inputs!$C$18) -> 21632 | F4: =C4+D4+E4 -> 306787 | G4: =B4 * Inputs!$B$22 -> 4870096.1 | H4: =B4 * Inputs!$B$23 -> 811682.69 | I4: =B4 * Inputs!$B$24 -> 487009.61 | J4: =B4 * Inputs!$B$25 -> 324673.07 | K4: =B4 * Inputs!$B$26 -> 811682.69 | L4: =G4+H4+I4+J4+K4 -> 7305144.2 | M4: =F4 + L4 -> 7611931.2
A5: 2028 | B5: ='Revenue Forecast'!N5 -> 17909656 | C5: =C4*(1+Inputs!C18) -> 58422 | D5: =D4 * (1 + Inputs!$C$17) -> 245008.6 | E5: =E4 * (1 + Inputs!$C$18) -> 22497.28 | F5: =C5+D5+E5 -> 325927.88 | G5: =B5 * Inputs!$B$22 -> 5372896.7 | H5: =B5 * Inputs!$B$23 -> 895482.78 | I5: =B5 * Inputs!$B$24 -> 537289.67 | J5: =B5 * Inputs!$B$25 -> 358193.11 | K5: =B5 * Inputs!$B$26 -> 895482.78 | L5: =G5+H5+I5+J5+K5 -> 8059345.1 | M5: =F5 + L5 -> 8385272.9
A6: 2029 | B6: ='Revenue Forecast'!N6 -> 19760111 | C6: =C5*(1+Inputs!C19) -> 58422 | D6: =D5 * (1 + Inputs!$C$17) -> 262159.2 | E6: =E5 * (1 + Inputs!$C$18) -> 23397.171 | F6: =C6+D6+E6 -> 343978.37 | G6: =B6 * Inputs!$B$22 -> 5928033.4 | H6: =B6 * Inputs!$B$23 -> 988005.57 | I6: =B6 * Inputs!$B$24 -> 592803.34 | J6: =B6 * Inputs!$B$25 -> 395202.23 | K6: =B6 * Inputs!$B$26 -> 988005.57 | L6: =G6+H6+I6+J6+K6 -> 8892050.1 | M6: =F6 + L6 -> 9236028.5
A7: 2030 | B7: ='Revenue Forecast'!N7 -> 21803323 | C7: =C6*(1+Inputs!C20) -> 58422 | D7: =D6 * (1 + Inputs!$C$17) -> 280510.35 | E7: =E6 * (1 + Inputs!$C$18) -> 24333.058 | F7: =C7+D7+E7 -> 363265.4 | G7: =B7 * Inputs!$B$22 -> 6540996.8 | H7: =B7 * Inputs!$B$23 -> 1090166.1 | I7: =B7 * Inputs!$B$24 -> 654099.68 | J7: =B7 * Inputs!$B$25 -> 436066.46 | K7: =B7 * Inputs!$B$26 -> 1090166.1 | L7: =G7+H7+I7+J7+K7 -> 9811495.3 | M7: =F7 + L7 -> 10174761

Sheet profit revenue desgin
A3: Row Labels | B3: Sum of Total Revenue | C3: Sum of Net Profit
A4: 2025 | B4: 13680000 | C4: 5316750
A5: 2026 | B5: 14418912 | C5: 5608576.2
A6: 2027 | B6: 16233654 | C6: 6342541.9
A7: 2028 | B7: 17909656 | C7: 7019537.1
A8: 2029 | B8: 19760111 | C8: 7769312.2
A9: 2030 | B9: 21803323 | C9: 8721421.6
A10: Grand Total | B10: 1.0380566e+08 | C10: 40778139

Sheet cost breakdown desgin
A3: Row Labels | B3: Sum of Total Variable Costs | C3: Sum of Total Fixed Costs
A4: 2025 | B4: 6156000 | C4: 270000
A5: 2026 | B5: 6488510.4 | C5: 287300
A6: 2027 | B6: 7305144.2 | C6: 306787
A7: 2028 | B7: 8059345.1 | C7: 325927.88
A8: 2029 | B8: 8892050.1 | C8: 343978.37
A9: 2030 | B9: 9811495.3 | C9: 363265.4
A10: Grand Total | B10: 46712545 | C10: 1897258.7

Sheet P&L (Profit & Loss)
A1: Year | B1: Total Revenue | C1: Total Variable Costs | D1: Total Fixed Costs | E1: EBITDA (Revenue – (Fixed + Variable)) | F1: Depreciation | G1: EBIT | H1: Interest | I1: Profit Before Tax | J1: Tax | K1: Net Profit
A2: 2025 | B2: ='Revenue Forecast'!N2 -> 13680000 | C2: ='Cost Breakdown'!L2 -> 6156000 | D2: ='Cost Breakdown'!F2 -> 270000 | E2: =B2-(C2+D2) -> 7254000 | F2: =Inputs!$B$37 * Inputs!$B$42 -> 115000 | G2: =E2-F2 -> 7139000 | H2: =Inputs!$B$31 * Inputs!$C$31 -> 50000 | I2: =G2-H2 -> 7089000 | J2: =I2 * Inputs!$B$41 -> 1772250 | K2: =I2-J2 -> 5316750
A3: 2026 | B3: ='Revenue Forecast'!N3 -> 14418912 | C3: ='Cost Breakdown'!L3 -> 6488510.4 | D3: ='Cost Breakdown'!F3 -> 287300 | E3: =B3-(C3+D3) -> 7643101.6 | F3: =Inputs!$B$37 * Inputs!$B$42 -> 115000 | G3: =E3-F3 -> 7528101.6 | H3: =Inputs!$B$31 * Inputs!$C$31 -> 50000 | I3: =G3-H3 -> 7478101.6 | J3: =I3 * Inputs!$B$41 -> 1869525.4 | K3: =I3-J3 -> 5608576.2
A4: 2027 | B4: ='Revenue Forecast'!N4 -> 16233654 | C4: ='Cost Breakdown'!L4 -> 7305144.2 | D4: ='Cost Breakdown'!F4 -> 306787 | E4: =B4-(C4+D4) -> 8621722.6 | F4: =Inputs!$B$37 * Inputs!$B$42 -> 115000 | G4: =E4-F4 -> 8506722.6 | H4: =Inputs!$B$31 * Inputs!$C$31 -> 50000 | I4: =G4-H4 -> 8456722.6 | J4: =I4 * Inputs!$B$41 -> 2114180.6 | K4: =I4-J4 -> 6342541.9
A5: 2028 | B5: ='Revenue Forecast'!N5 -> 17909656 | C5: ='Cost Breakdown'!L5 -> 8059345.1 | D5: ='Cost Breakdown'!F5 -> 325927.88 | E5: =B5-(C5+D5) -> 9524382.7 | F5: =Inputs!$B$37 * Inputs!$B$42 -> 115000 | G5: =E5-F5 -> 9409382.7 | H5: =Inputs!$B$31 * Inputs!$C$31 -> 50000 | I5: =G5-H5 -> 9359382.7 | J5: =I5 * Inputs!$B$41 -> 2339845.7 | K5: =I5-J5 -> 7019537.1
A6: 2029 | B6: ='Revenue Forecast'!N6 -> 19760111 | C6: ='Cost Breakdown'!L6 -> 8892050.1 | D6: ='Cost Breakdown'!F6 -> 343978.37 | E6: =B6-(C6+D6) -> 10524083 | F6: =Inputs!$B$37 * Inputs!$B$42 -> 115000 | G6: =E6-F6 -> 10409083 | H6: =Inputs!$B$31 * Inputs!$C$31 -> 50000 | I6: =G6-H6 -> 10359083 | J6: =I6 * Inputs!$B$41 -> 2589770.7 | K6: =I6-J6 -> 7769312.2
A7: 2030 | B7: ='Revenue Forecast'!N7 -> 21803323 | C7: ='Cost Breakdown'!L7 -> 9811495.3 | D7: ='Cost Breakdown'!F7 -> 363265.4 | E7: =B7-(C7+D7) -> 11628562 | F7: 0 | G7: =E7-F7 -> 11628562 | H7: 0 | I7: =G7-H7 -> 11628562 | J7: =I7 * Inputs!$B$41 -> 2907140.5 | K7: =I7-J7 -> 8721421.6

Sheet Cash Flow
A2: Account / Title | B2: 2025 | C2: 2026 | D2: 2027 | E2: 2028 | F2: 2029 | G2: 2030
A3: Operating Activities
A4: Net Profit (from P&L) | B4: ='P&L (Profit & Loss)'!K2 -> 5316750 | C4: ='P&L (Profit & Loss)'!K3 -> 5608576.2 | D4: ='P&L (Profit & Loss)'!K4 -> 6342541.9 | E4: ='P&L (Profit & Loss)'!K5 -> 7019537.1 | F4: ='P&L (Profit & Loss)'!K6 -> 7769312.2 | G4: ='P&L (Profit & Loss)'!K7 -> 8721421.6
A5: Add: Depreciation & Amortization | B5: ='P&L (Profit & Loss)'!F2 -> 115000 | C5: ='P&L (Profit & Loss)'!F3 -> 115000 | D5: ='P&L (Profit & Loss)'!F4 -> 115000 | E5: ='P&L (Profit & Loss)'!F5 -> 115000 | F5: ='P&L (Profit & Loss)'!F6 -> 115000 | G5: ='P&L (Profit & Loss)'!F7 -> 0
A6: Less: Increase in Accounts Receivable | B6: ='Balance Sheet'!B5 -> 1124383.6 | C6: ='Balance Sheet'!C5 - 'Balance Sheet'!B5 -> 60732.493 | D6: ='Balance Sheet'!D5 - 'Balance Sheet'!C5 -> 149156.86 | E6: ='Balance Sheet'!E5 - 'Balance Sheet'!D5 -> 137753.58 | F6: ='Balance Sheet'!F5 - 'Balance Sheet'!E5 -> 152092.25 | G6: ='Balance Sheet'!G5 - 'Balance Sheet'!F5 -> 167935.19
A7: Less: Increase in Inventory | B7: ='Balance Sheet'!B6 -> 337315.07 | C7: ='Balance Sheet'!C6 - 'Balance Sheet'!B6 -> 18219.748 | D7: ='Balance Sheet'!D6 - 'Balance Sheet'!C6 -> 44747.057 | E7: ='Balance Sheet'!E6 - 'Balance Sheet'!D6 -> 41326.075 | F7: ='Balance Sheet'!F6 - 'Balance Sheet'!E6 -> 45627.674 | G7: ='Balance Sheet'!G6 - 'Balance Sheet'!F6 -> 50380.556
A8: Add: Increase in Accounts Payable | B8: ='Balance Sheet'!B16 -> 421643.84 | C8: ='Balance Sheet'!C16 - 'Balance Sheet'!B16 -> 22774.685 | D8: ='Balance Sheet'!D16 - 'Balance Sheet'!C16 -> 55933.821 | E8: ='Balance Sheet'!E16 - 'Balance Sheet'!D16 -> 51657.594 | F8: ='Balance Sheet'!F16 - 'Balance Sheet'!E16 -> 57034.593 | G8: ='Balance Sheet'!G16 - 'Balance Sheet'!F16 -> 62975.696
A9: Net Cash from Operating Activities | B9: =B4+B5-B6-B7+B8 -> 4391695.2 | C9: =C4+C5-C6-C7+C8 -> 5667398.6 | D9: =D4+D5-D6-D7+D8 -> 6319571.8 | E9: =E4+E5-E6-E7+E8 -> 7007115 | F9: =F4+F5-F6-F7+F8 -> 7743626.8 | G9: =G4+G5-G6-G7+G8 -> 8566081.6
A10: Investing Activities
A11: Capital Expenditures (CapEx) | B11: =-1150000 -> -1150000 | C11: =0 -> 0 | D11: =0 -> 0 | E11: =0 -> 0 | F11: =0 -> 0 | G11: =0 -> 0
A12: Net Cash from Investing Activities | B12: =-1150000 -> -1150000 | C12: =0 -> 0 | D12: =0 -> 0 | E12: =0 -> 0 | F12: =0 -> 0 | G12: =0 -> 0
A13: Financing Activities
A14: Loan Drawdown (+) | B14: 500000 | C14: 0 | D14: 0 | E14: 0 | F14: 0 | G14: 0
A15: Loan Principal Repayment (-) | B15: 0 | C15: =100000 -> 100000 | D15: =100000 -> 100000 | E15: =100000 -> 100000 | F15: =100000 -> 100000 | G15: =100000 -> 100000
A16: Equity Injection (+) | B16: 0 | C16: 0 | D16: 0 | E16: 0 | F16: 0 | G16: 0
A17: Dividend Paid (-) | B17: 0 | C17: 0 | D17: 0 | E17: 0 | F17: 0 | G17: 0
A18: Net Cash from Financing Activities | B18: =B14-B15+B16-B17 -> 500000 | C18: =C14-C15+C16-C17 -> -100000 | D18: =D14-D15+D16-D17 -> -100000 | E18: =E14-E15+E16-E17 -> -100000 | F18: =F14-F15+F16-F17 -> -100000 | G18: =G14-G15+G16-G17 -> -100000
A19: Net Change in Cash | B19: =B9+B12+B18 -> 3741695.2 | C19: =C9+C12+C18 -> 5567398.6 | D19: =D9+D12+D18 -> 6219571.8 | E19: =E9+E12+E18 -> 6907115 | F19: =F9+F12+F18 -> 7643626.8 | G19: =G9+G12+G18 -> 8466081.6
A20: Opening Cash Balance | B20: 1000000 | C20: 4741695 | D20: 10309094 | E20: 16528666 | F20: 23435781 | G20: 31079408
A21: Closing Cash Balance (Link to B/S) | B21: =B19+B20 -> 4741695.2 | C21: =C19+C20 -> 10309094 | D21: =D19+D20 -> 16528666 | E21: =E19+E20 -> 23435781 | F21: =F19+F20 -> 31079408 | G21: =G19+G20 -> 39545490

Sheet Balance Sheet
A1: Account / Title | B1: 2025 | C1: 2026 | D1: 2027 | E1: 2028 | F1: 2029 | G1: 2030
A2: ASSETS
A3: Current Assets
A4: Cash & Cash Equivalents | B4: ='Cash Flow'!B21 -> 4741695.2 | C4: ='Cash Flow'!C21 -> 10309094 | D4: ='Cash Flow'!D21 -> 16528666 | E4: ='Cash Flow'!E21 -> 23435781 | F4: ='Cash Flow'!F21 -> 31079408 | G4: ='Cash Flow'!G21 -> 39545490
A5: Accounts Receivable | B5: =('P&L (Profit & Loss)'!B2 * Inputs!B46 / 365) -> 1124383.6 | C5: =('P&L (Profit & Loss)'!B3* Inputs!B46 / 365) -> 1185116.1 | D5: =('P&L (Profit & Loss)'!B4 * Inputs!B46 / 365) -> 1334272.9 | E5: =('P&L (Profit & Loss)'!B5 * Inputs!B46 / 365) -> 1472026.5 | F5: =('P&L (Profit & Loss)'!B6 * Inputs!B46 / 365) -> 1624118.7 | G5: =('P&L (Profit & Loss)'!B7 * Inputs!B46 / 365) -> 1792053.9
A6: Inventory | B6: =('P&L (Profit & Loss)'!C2 * Inputs!B47/ 365) -> 337315.07 | C6: =('P&L (Profit & Loss)'!C3 * Inputs!B47/ 365) -> 355534.82 | D6: =('P&L (Profit & Loss)'!C4 * Inputs!B47/ 365) -> 400281.87 | E6: =('P&L (Profit & Loss)'!C5 * Inputs!B47/ 365) -> 441607.95 | F6: =('P&L (Profit & Loss)'!C6 * Inputs!B47/ 365) -> 487235.62 | G6: =('P&L (Profit & Loss)'!C7* Inputs!B47/ 365) -> 537616.18
A7: Other Current Assets | B7: 0 | C7: 0 | D7: 0 | E7: 0 | G7: 0
A8: Total Current Assets | B8: =SUM(B3:B6) -> 6203393.8 | C8: =C4+C5+C6 -> 11849745 | D8: =D4+D5+D6 -> 18263221 | E8: =E4+E5+E6 -> 25349415 | F8: =F4+F5+F6 -> 33190762 | G8: =G4+G5+G6 -> 41875160
A9: Fixed Assets (Gross) | B9: 1150000 | C9: 1150000 | D9: 1150000 | E9: 1150000 | F9: 1150000 | G9: 1150000
A10: Less: Accumulated Depreciation | B10: 115000 | C10: =B10 + 'P&L (Profit & Loss)'!F3 -> 230000 | D10: =C10 + 'P&L (Profit & Loss)'!F4 -> 345000 | E10: =D10 + 'P&L (Profit & Loss)'!F5 -> 460000 | F10: =E10 + 'P&L (Profit & Loss)'!F6 -> 575000 | G10: =F10 + 'P&L (Profit & Loss)'!F7 -> 575000
A11: Net Fixed Assets | B11: =B9-B10 -> 1035000 | C11: =C9-C10 -> 920000 | D11: =D9-D10 -> 805000 | E11: =E9-E10 -> 690000 | F11: =F9-F10 -> 575000 | G11: =G9-G10 -> 575000
A12: Total Assets | B12: =B8+B11 -> 7238393.8 | C12: =C8+C11 -> 12769745 | D12: =D8+D11 -> 19068221 | E12: =E8+E11 -> 26039415 | F12: =F8+F11 -> 33765762 | G12: =G8+G11 -> 42450160
A14: LIABILITIES & EQUITY
A15: Current Liabilities
A16: Accounts Payable | B16: =('P&L (Profit & Loss)'!C2* Inputs!B48 / 365) -> 421643.84 | C16: =('P&L (Profit & Loss)'!C3* Inputs!B48 / 365) -> 444418.52 | D16: =('P&L (Profit & Loss)'!C4* Inputs!B48 / 365) -> 500352.34 | E16: =('P&L (Profit & Loss)'!C5* Inputs!B48 / 365) -> 552009.94 | F16: =('P&L (Profit & Loss)'!C6* Inputs!B48 / 365) -> 609044.53 | G16: =('P&L (Profit & Loss)'!C7* Inputs!B48 / 365) -> 672020.22
A17: Short-Term Debt | B17: =IF(COLUMN()-COLUMN($B$17)+1 <= Inputs!$D$31, Inputs!$B$31/Inputs!$D$31, 0) -> 100000 | C17: =IF(COLUMN()-COLUMN($B$17)+1 <= Inputs!$D$31, Inputs!$B$31/Inputs!$D$31, 0) -> 100000 | D17: =IF(COLUMN()-COLUMN($B$17)+1 <= Inputs!$D$31, Inputs!$B$31/Inputs!$D$31, 0) -> 100000 | E17: =IF(COLUMN()-COLUMN($B$17)+1 <= Inputs!$D$31, Inputs!$B$31/Inputs!$D$31, 0) -> 100000 | F17: =IF(COLUMN()-COLUMN($B$17)+1 <= Inputs!$D$31, Inputs!$B$31/Inputs!$D$31, 0) -> 100000 | G17: =IF(COLUMN()-COLUMN($B$17)+1 <= Inputs!$D$31, Inputs!$B$31/Inputs!$D$31, 0) -> 0
A18: Other Current Liabilities | B18: 0 | C18: 0 | D18: 0 | E18: 0 | F18: 0 | G18: 0
A19: Total Current Liabilities | B19: =B16+B17 -> 521643.84 | C19: =C16+C17 -> 544418.52 | D19: =D16+D17 -> 600352.34 | E19: =E16+E17 -> 652009.94 | F19: =F16+F17 -> 709044.53 | G19: =G16+G17 -> 672020.22
A20: Long-Term Debt | B20: 400000 | C20: =B20 - 'Cash Flow'!C15 -> 300000 | D20: =C20 - 'Cash Flow'!D15 -> 200000 | E20: =D20 - 'Cash Flow'!E15 -> 100000 | F20: =E20 - 'Cash Flow'!F15 -> 0 | G20: =MAX(0, F18 - 'Cash Flow'!G15) -> 0
A21: Total Liabilities | B21: =B19+B20 -> 921643.84 | C21: =C19+C20 -> 844418.52 | D21: =D19+D20 -> 800352.34 | E21: =E19+E20 -> 752009.94 | F21: =F19+F20 -> 709044.53 | G21: =G19+G20 -> 672020.22
A22: Equity
A23: Share Capital | B23: 1000000 | C23: 1000000 | D23: 1000000 | E23: 1000000 | F23: 1000000 | G23: 1000000
A24: Retained Earnings | B24: ='P&L (Profit & Loss)'!K2 -> 5316750 | C24: =B24 + 'P&L (Profit & Loss)'!K3 -> 10925326 | D24: =C24 + 'P&L (Profit & Loss)'!K4 -> 17267868 | E24: =D24 + 'P&L (Profit & Loss)'!K5 -> 24287405 | F24: =E24 + 'P&L (Profit & Loss)'!K6 -> 32056717 | G24: =F24 + 'P&L (Profit & Loss)'!K7 -> 40778139
A25: Total Equity | B25: =B23+B24 -> 6316750 | C25: =C23+C24 -> 11925326 | D25: =D23+D24 -> 18267868 | E25: =E23+E24 -> 25287405 | F25: =F23+F24 -> 33056717 | G25: =G23+G24 -> 41778139
A26: Total Liabilities & Equity | B26: =B21+B25 -> 7238393.8 | C26: =C21+C25 -> 12769745 | D26: =D21+D25 -> 19068220 | E26: =E21+E25 -> 26039415 | F26: =F21+F25 -> 33765762 | G26: =G21+G25 -> 42450159

Sheet Break-Even
A1: Year | B1: Total Revenue | C1: Total Variable Cost | D1: Contribution per unit | E1: Total Contribution (CM) | F1: Fixed Costs (total) | G1: Break-even Units | H1: Break-even Sales Value | I1: Margin of Safety (%)
A2: 2025 | B2: ='P&L (Profit & Loss)'!B2 -> 13680000 | C2: ='P&L (Profit & Loss)'!C2 -> 6156000 | D2: =E2/ Inputs!$C$12 -> 368.82353 | E2: =B2-C2 -> 7524000 | F2: ='P&L (Profit & Loss)'!D2 -> 270000 | G2: =F2/D2 -> 732.05742 | H2: =G2* (B2 / Inputs!$C$12) -> 490909.09 | I2: =(Inputs!$C$12 - G2) / Inputs!$C$12 -> 0.96411483
A3: 2026 | B3: ='P&L (Profit & Loss)'!B3 -> 14418912 | C3: ='P&L (Profit & Loss)'!C3 -> 6488510.4 | D3: =E3/ Inputs!$C$12 -> 388.74518 | E3: =B3-C3 -> 7930401.6 | F3: ='P&L (Profit & Loss)'!D3 -> 287300 | G3: =F3/D3 -> 739.04454 | H3: =G3* (B3 / Inputs!$C$12) -> 522363.64 | I3: =(Inputs!$C$12 - G3) / Inputs!$C$12 -> 0.96377233
A4: 2027 | B4: ='P&L (Profit & Loss)'!B4 -> 16233654 | C4: ='P&L (Profit & Loss)'!C4 -> 7305144.2 | D4: =E4/ Inputs!$C$12 -> 437.67204 | E4: =B4-C4 -> 8928509.6 | F4: ='P&L (Profit & Loss)'!D4 -> 306787 | G4: =F4/D4 -> 700.95179 | H4: =G4* (B4 / Inputs!$C$12) -> 557794.55 | I4: =(Inputs!$C$12 - G4) / Inputs!$C$12 -> 0.96563962
A5: 2028 | B5: ='P&L (Profit & Loss)'!B5 -> 17909656 | C5: ='P&L (Profit & Loss)'!C5 -> 8059345.1 | D5: =E5/ Inputs!$C$12 -> 482.85836 | E5: =B5-C5 -> 9850310.6 | F5: ='P&L (Profit & Loss)'!D5 -> 325927.88 | G5: =F5/D5 -> 674.99686 | H5: =G5* (B5 / Inputs!$C$12) -> 592596.15 | I5: =(Inputs!$C$12 - G5) / Inputs!$C$12 -> 0.96691192
A6: 2029 | B6: ='P&L (Profit & Loss)'!B6 -> 19760111 | C6: ='P&L (Profit & Loss)'!C6 -> 8892050.1 | D6: =E6/ Inputs!$C$12 -> 532.7481 | E6: =B6-C6 -> 10868061 | F6: ='P&L (Profit & Loss)'!D6 -> 343978.37 | G6: =F6/D6 -> 645.66795 | H6: =G6* (B6 / Inputs!$C$12) -> 625415.22 | I6: =(Inputs!$C$12 - G6) / Inputs!$C$12 -> 0.96834961
A7: 2030 | B7: ='P&L (Profit & Loss)'!B7 -> 21803323 | C7: ='P&L (Profit & Loss)'!C7 -> 9811495.3 | D7: =E7/ Inputs!$C$12 -> 587.83468 | E7: =B7-C7 -> 11991828 | F7: ='P&L (Profit & Loss)'!D7 -> 363265.4 | G7: =F7/D7 -> 617.97205 | H7: =G7* (B7 / Inputs!$C$12) -> 660482.55 | I7: =(Inputs!$C$12 - G7) / Inputs!$C$12 -> 0.96970725

Sheet Dashboard
A5: ='P&L (Profit & Loss)'!B2-'P&L (Profit & Loss)'!C2 -> 7524000
